<?xml version="1.0" encoding="UTF-8"?>
<robot name="Robot">
    <link name="arm1">
        <inertial>
            <origin rpy="0 0 0" xyz="0.00000000 0.00000000 0.00000000"/>
            <mass value="1.00000000"/>
            <inertia ixx="1.00000000" ixy="0.00000000" ixz="0.00000000" iyy="1.00000000" iyz="0.00000000" izz="1.00000000"/>
        </inertial>
        <visual>
            <origin rpy="1.57075 0 1.57075" xyz="0.00000000 0.00000000 -0.7"/>
            <geometry>
               <mesh filename="package://your_robot_package/meshes/p1.stl" scale="0.001 0.001 0.001"/>
            </geometry>
            <material name="">
                <color rgba="0.124 0.098 0.2044 1.00000000"/>
            </material>
        </visual>
    </link>
    <link name="arm2">
        <inertial>
            <origin rpy="0.00000000 0.00000000 0.00000000" xyz="0.00000000 0.00000000 0.00000000"/>
            <mass value="1.00000000"/>
            <inertia ixx="1.00000000" ixy="0.00000000" ixz="0.00000000" iyy="1.00000000" iyz="0.00000000" izz="1.00000000"/>
        </inertial>
        <visual>
            <origin rpy="0.00000000 -1.57075 3.1415" xyz="-0.4 0.7 0"/>
            <geometry>
               <mesh filename="package://your_robot_package/meshes/p2.stl" scale="0.001 0.001 0.001"/>
            </geometry>
            <material name="">
                <color rgba="0.266 0.098 0.2044 1.00000000"/>
            </material>
        </visual>
    </link>
    <link name="arm3">
        <inertial>
            <origin rpy="0.00000000 0.00000000 0.00000000" xyz="0.00000000 0.00000000 0.00000000"/>
            <mass value="1.00000000"/>
            <inertia ixx="1.00000000" ixy="0.00000000" ixz="0.00000000" iyy="1.00000000" iyz="0.00000000" izz="1.00000000"/>
        </inertial>
        <visual>
            <origin rpy="0.00000000 0.00000000 0.00000000" xyz="0 -0.744 -2.9"/>
            <geometry>
               <mesh filename="package://your_robot_package/meshes/p2_1.stl" scale="0.001 0.001 0.001"/>
            </geometry>
            <material name="">
                <color rgba="0.4088 0.098 0.2044 1.00000000"/>
            </material>
        </visual>
    </link>
    <link name="arm4">
        <inertial>
            <origin rpy="0.00000000 0.00000000 0.00000000" xyz="0.00000000 0.00000000 0.00000000"/>
            <mass value="1.00000000"/>
            <inertia ixx="1.00000000" ixy="0.00000000" ixz="0.00000000" iyy="1.00000000" iyz="0.00000000" izz="1.00000000"/>
        </inertial>
        <visual>
            <origin rpy="0.00000000 0 3.1415" xyz="0.00000000 0.750 -2.9"/>
            <geometry>
               <mesh filename="package://your_robot_package/meshes/rot.stl" scale="0.001 0.001 0.001"/>
            </geometry>
            <material name="">
                <color rgba="0.5511 0.098 0.2044 1.00000000"/>
            </material>
        </visual>
    </link>
    <link name="arm5">
        <inertial>
            <origin rpy="0.00000000 0.00000000 0.00000000" xyz="0.00000000 0.00000000 0.00000000"/>
            <mass value="1.00000000"/>
            <inertia ixx="1.00000000" ixy="0.00000000" ixz="0.00000000" iyy="1.00000000" iyz="0.00000000" izz="1.00000000"/>
        </inertial>
        <visual>
            <origin rpy="-3.1415 -1.57075 0" xyz="-3.000000 0.5 -0.5"/>
            <geometry>
               <mesh filename="package://your_robot_package/meshes/p4.stl" scale="0.001 0.001 0.001"/>
            </geometry>
            <material name="">
                <color rgba="0.69333 0.098 0.2044 1.0"/>
            </material>
        </visual>
    </link>
    <link name="arm6">
        <inertial>
            <origin rpy="0.00000000 0.00000000 0.00000000" xyz="0.00000000 0.00000000 0.00000000"/>
            <mass value="1.00000000"/>
            <inertia ixx="1.00000000" ixy="0.00000000" ixz="0.00000000" iyy="1.00000000" iyz="0.00000000" izz="1.00000000"/>
        </inertial>
        <visual>
            <origin rpy="0.00000000 0.00000000 0.00000000" xyz="0.00000000 0.00000000 0"/>
            <geometry>
               <box size = "0.1 0.1 0.220" />
            </geometry>
            <material name="">
                <color rgba="0.69333 0.098 0.2044 1.00000000"/>
            </material>
        </visual>
    </link>
    <link name="base">
        <inertial>
            <mass value="0"/>
            <inertia ixx="0" ixy="0" ixz="0" iyy="0" iyz="0" izz="0"/>
        </inertial>
    </link>
    <link name="endeffector">
        <inertial>
            <origin rpy="0.00000000 0.00000000 0.00000000" xyz="0.00000000 0.00000000 0.00000000"/>
            <mass value="1.00000000"/>
            <inertia ixx="1.00000000" ixy="0.00000000" ixz="0.00000000" iyy="1.00000000" iyz="0.00000000" izz="1.00000000"/>
        </inertial>
    </link>
    <joint name="endeffector_jnt" type="fixed">
        <parent link="arm6"/>
        <child link="endeffector"/>
        <origin rpy="0.00000000 0.00000000 0.00000000" xyz="0.00000000 0.00000000 0.00000000"/>
        <axis xyz="1.00000000 0.00000000 0.00000000"/>
    </joint>
    <joint name="jnt1" type="revolute">
        <parent link="base"/>
        <child link="arm1"/>
        <origin rpy="0.00000000 0.00000000 0.00000000" xyz="0.00000000 0.00000000 0.00000000"/>
        <axis xyz="0.00000000 0.00000000 1.00000000"/>
        <limit lower="-3.14159265" upper="3.14159265" effort="0" velocity="0"/>
    </joint>
    <joint name="jnt2" type="revolute">
        <parent link="arm1"/>
        <child link="arm2"/>
        <origin rpy="-1.57079633  0.00000000  0.00000000" xyz="0.22000000 0.00000000 0.00000000"/>
        <axis xyz="0.00000000 0.00000000 1.00000000"/>
        <limit lower="-3.14159265" upper="3.14159265" effort="0" velocity="0"/>
    </joint>
    <joint name="jnt3" type="prismatic">
        <parent link="arm2"/>
        <child link="arm3"/>
        <origin rpy="0.00000000 1.57079633 0.00000000" xyz="2.41380000 -0.02450000  0.00000000"/>
        <axis xyz="1.00000000 0.00000000 0.00000000"/>
        <limit lower="-0.50000000" upper="0.50000000" effort="0" velocity="0"/>
    </joint>
    <joint name="jnt4" type="revolute">
        <parent link="arm3"/>
        <child link="arm4"/>
        <origin rpy="0.00000000 0.00000000 0.00000000" xyz="0.00000000 0.00000000 0.00000000"/>
        <axis xyz="0.00000000 0.00000000 1.00000000"/>
        <limit lower="-3.14159265" upper="3.14159265" effort="0" velocity="0"/>
    </joint>
    <joint name="jnt5" type="revolute">
        <parent link="arm4"/>
        <child link="arm5"/>
        <origin rpy="0.00000000 -1.57079633  0.00000000" xyz="-0.58290000  0.26500000  0.10300000"/>
        <axis xyz="0.00000000 0.00000000 1.00000000"/>
        <limit lower="-3.14159265" upper="3.14159265" effort="0" velocity="0"/>
    </joint>
    <joint name="jnt6" type="prismatic">
        <parent link="arm5"/>
        <child link="arm6"/>
        <origin rpy="1.57079633 0.00000000 0.00000000" xyz="0.11300000 0.88200000 0.00000000"/>
        <axis xyz="0.00000000 0.00000000 1.00000000"/>
        <limit lower="-0.50000000" upper="0.50000000" effort="0" velocity="0"/>
    </joint>
</robot>
